Workbook

Sheet Lars B
A1: Jahr | B1: 2026 | F1: / = Wochenende | AB1: 4 Stunden - 24 Dezember
A2: MA: | B2: Lars Bölecke | F2: U=Urlaub | AB2: 4 Stunden - 31 Dezember
F3: K=Krank
F4: KK=Kindkrank
F5: F=Feiertag
D7: Arbeitstag
B8: Monat | C8: Projekt | D8: 1 | E8: 2 | F8: 3 | G8: 4 | H8: 5 | I8: 6 | J8: 7 | K8: 8 | L8: 9 | M8: 10 | N8: 11 | O8: 12 | P8: 13 | Q8: 14 | R8: 15 | S8: 16 | T8: 17 | U8: 18 | V8: 19 | W8: 20 | X8: 21 | Y8: 22 | Z8: 23 | AA8: 24 | AB8: 25 | AC8: 26 | AD8: 27 | AE8: 28 | AF8: 29 | AG8: 30 | AH8: 31 | AI8: Arbeitsstunden | AJ8: Urlaubstunden | AK8: Feiertag
B9: Januar | C9: POLYVETEX | D9: F | E9: U | F9: / | G9: / | M9: / | N9: / | T9: / | U9: / | AA9: / | AB9: / | AH9: / | AI9: =SUM(D9:E9,H9:L9,O9:S9,V9:Z9,AC9:AG9) -> 0 | AJ9: 8 | AK9: 8
C10: ENKOS | D10: F | E10: U | F10: / | G10: / | M10: / | N10: / | T10: / | U10: / | AA10: / | AB10: / | AH10: / | AI10: =SUM(D10:E10,H10:L10,O10:S10,V10:Z10,AC10:AG10) -> 0
B11: 20 Arbeitstage | C11: ESSENCE | D11: F | E11: U | F11: / | G11: / | M11: / | N11: / | T11: / | U11: / | AA11: / | AB11: / | AH11: / | AI11: =SUM(D11:E11,H11:L11,O11:S11,V11:Z11,AC11:AG11) -> 0
C12: IDLE | D12: F | E12: U | F12: / | G12: / | M12: / | N12: / | T12: / | U12: / | AA12: / | AB12: / | AH12: / | AI12: =SUM(D12:E12,H12:L12,O12:S12,V12:Z12,AC12:AG12) -> 0
B13: 160 | C13: AREALIGHT | D13: F | E13: U | F13: / | G13: / | M13: / | N13: / | T13: / | U13: / | AA13: / | AB13: / | AH13: / | AI13: =SUM(D13:E13,H13:L13,O13:S13,V13:Z13,AC13:AG13) -> 0
C14: MR ASSIST | D14: F | E14: U | F14: / | G14: / | M14: / | N14: / | T14: / | U14: / | AA14: / | AB14: / | AH14: / | AI14: =SUM(D14:E14,H14:L14,O14:S14,V14:Z14,AC14:AG14) -> 0
B15: 1 Feiertag | C15: HEATFLUXTEX | D15: F | E15: U | F15: / | G15: / | M15: / | N15: / | T15: / | U15: / | AA15: / | AB15: / | AH15: / | AI15: =SUM(D15:E15,H15:L15,O15:S15,V15:Z15,AC15:AG15) -> 0
B16: 1Betrieburlaub | C16: FLEXtexIR | D16: F | E16: U | F16: / | G16: / | M16: / | N16: / | T16: / | U16: / | AA16: / | AB16: / | AH16: / | AI16: =SUM(D16:E16,H16:L16,O16:S16,V16:Z16,AC16:AG16) -> 0
C17: SOLARGROW | D17: F | E17: U | F17: / | G17: / | M17: / | N17: / | T17: / | U17: / | AA17: / | AB17: / | AH17: / | AI17: =SUM(D17:E17,H17:L17,O17:S17,V17:Z17,AC17:AG17) -> 0
C18: TEXWELD | D18: F | E18: U | F18: / | G18: / | M18: / | N18: / | T18: / | U18: / | AA18: / | AB18: / | AH18: / | AI18: =SUM(D18:E18,H18:L18,O18:S18,V18:Z18,AC18:AG18) -> 0
AI19: =SUM(AI9:AI18) -> 0 | AK19: =SUM(AI19,AJ9:AK9) -> 16
B20: Februar | C20: POLYVETEX | D20: / | J20: / | K20: / | Q20: / | R20: / | X20: / | Y20: / | AE20: / | AF20: / | AI20: =SUM(E20:I20,L20:P20,S20:W20,Z20:AD20) -> 0 | AK20: 0
C21: ENKOS | D21: / | J21: / | K21: / | Q21: / | R21: / | X21: / | Y21: / | AE21: / | AF21: / | AI21: =SUM(E21:I21,L21:P21,S21:W21,Z21:AD21) -> 0
B22: 20 Arbeitstage | C22: ESSENCE | D22: / | J22: / | K22: / | Q22: / | R22: / | X22: / | Y22: / | AE22: / | AF22: / | AI22: =SUM(E22:I22,L22:P22,S22:W22,Z22:AD22) -> 0
C23: IDLE | D23: / | J23: / | K23: / | Q23: / | R23: / | X23: / | Y23: / | AE23: / | AF23: / | AI23: =SUM(E23:I23,L23:P23,S23:W23,Z23:AD23) -> 0
B24: 168 | C24: AREALIGHT | D24: / | J24: / | K24: / | Q24: / | R24: / | X24: / | Y24: / | AE24: / | AF24: / | AI24: =SUM(E24:I24,L24:P24,S24:W24,Z24:AD24) -> 0
C25: MR ASSIST | D25: / | J25: / | K25: / | Q25: / | R25: / | X25: / | Y25: / | AE25: / | AF25: / | AI25: =SUM(E25:I25,L25:P25,S25:W25,Z25:AD25) -> 0
C26: HEATFLUXTEX | D26: / | J26: / | K26: / | Q26: / | R26: / | X26: / | Y26: / | AE26: / | AF26: / | AI26: =SUM(E26:I26,L26:P26,S26:W26,Z26:AD26) -> 0
C27: FLEXtexIR | D27: / | J27: / | K27: / | Q27: / | R27: / | X27: / | Y27: / | AE27: / | AF27: / | AI27: =SUM(E27:I27,L27:P27,S27:W27,Z27:AD27) -> 0
C28: SOLARGROW | D28: / | J28: / | K28: / | Q28: / | R28: / | X28: / | Y28: / | AE28: / | AF28: / | AI28: =SUM(E28:I28,L28:P28,S28:W28,Z28:AD28) -> 0
C29: TEXWELD | D29: / | J29: / | K29: / | Q29: / | R29: / | X29: / | Y29: / | AE29: / | AF29: / | AI29: =SUM(E29:I29,L29:P29,S29:W29,Z29:AD29) -> 0
AI30: =SUM(AI20:AI29) -> 0 | AK30: =SUM(AI30,AJ20:AK20) -> 0
B31: März | C31: POLYVETEX | D31: / | J31: / | K31: / | Q31: / | R31: / | X31: / | Y31: / | AE31: / | AF31: / | AI31: =SUM(E31:I31,L31:P31,S31:W31,Z31:AD31,AG31:AH31) -> 0 | AK31: 0
C32: ENKOS | D32: / | J32: / | K32: / | Q32: / | R32: / | X32: / | Y32: / | AE32: / | AF32: / | AI32: =SUM(E32:I32,L32:P32,S32:W32,Z32:AD32,AG32:AH32) -> 0
B33: 22 Arbeitstage | C33: ESSENCE | D33: / | J33: / | K33: / | Q33: / | R33: / | X33: / | Y33: / | AE33: / | AF33: / | AI33: =SUM(E33:I33,L33:P33,S33:W33,Z33:AD33,AG33:AH33) -> 0
C34: IDLE | D34: / | J34: / | K34: / | Q34: / | R34: / | X34: / | Y34: / | AE34: / | AF34: / | AI34: =SUM(E34:I34,L34:P34,S34:W34,Z34:AD34,AG34:AH34) -> 0
B35: 176 | C35: AREALIGHT | D35: / | J35: / | K35: / | Q35: / | R35: / | X35: / | Y35: / | AE35: / | AF35: / | AI35: =SUM(E35:I35,L35:P35,S35:W35,Z35:AD35,AG35:AH35) -> 0
C36: MR ASSIST | D36: / | J36: / | K36: / | Q36: / | R36: / | X36: / | Y36: / | AE36: / | AF36: / | AI36: =SUM(E36:I36,L36:P36,S36:W36,Z36:AD36,AG36:AH36) -> 0
C37: HEATFLUXTEX | D37: / | J37: / | K37: / | Q37: / | R37: / | X37: / | Y37: / | AE37: / | AF37: / | AI37: =SUM(E37:I37,L37:P37,S37:W37,Z37:AD37,AG37:AH37) -> 0
C38: FLEXtexIR | D38: / | J38: / | K38: / | Q38: / | R38: / | X38: / | Y38: / | AE38: / | AF38: / | AI38: =SUM(E38:I38,L38:P38,S38:W38,Z38:AD38,AG38:AH38) -> 0
C39: SOLARGROW | D39: / | J39: / | K39: / | Q39: / | R39: / | X39: / | Y39: / | AE39: / | AF39: / | AI39: =SUM(E39:I39,L39:P39,S39:W39,Z39:AD39,AG39:AH39) -> 0
C40: TEXWELD | D40: / | J40: / | K40: / | Q40: / | R40: / | X40: / | Y40: / | AE40: / | AF40: / | AI40: =SUM(E40:I40,L40:P40,S40:W40,Z40:AD40,AG40:AH40) -> 0
AI41: =SUM(AI31:AI40) -> 0 | AK41: =SUM(AI41,AJ31:AK31) -> 0
...

Sheet Lena S
A1: Jahr | B1: 2025 | F1: / = Wochenende | AB1: 4 Stunden - 24 Dezember
A2: MA: | B2: Mitarbeiter: | C2: Lena Sergio | F2: U=Urlaub | AB2: 4 Stunden - 31 Dezember
F3: K=Krank
F4: KK=Kindkrank
F5: F=Feiertag
D7: Arbeitstag
A8: Monat | B8: Monat | C8: Projekt | D8: 1 | E8: 2 | F8: 3 | G8: 4 | H8: 5 | I8: 6 | J8: 7 | K8: 8 | L8: 9 | M8: 10 | N8: 11 | O8: 12 | P8: 13 | Q8: 14 | R8: 15 | S8: 16 | T8: 17 | U8: 18 | V8: 19 | W8: 20 | X8: 21 | Y8: 22 | Z8: 23 | AA8: 24 | AB8: 25 | AC8: 26 | AD8: 27 | AE8: 28 | AF8: 29 | AG8: 30 | AH8: 31 | AI8: Arbeitsstunden | AJ8: Urlaubstunden | AK8: Feiertag | AL8: Krank
B9: Juli | C9: STIMULATE | H9: / | I9: / | O9: / | P9: / | V9: / | W9: / | AC9: / | AD9: / | AI9: =SUM(D9:G9,J9:N9,Q9:U9,X9:AB9,AE9:AH9) -> 0 | AJ9: 0 | AK9: 0
C10: ENKOS | H10: / | I10: / | O10: / | P10: / | V10: / | W10: / | AC10: / | AD10: / | AI10: =SUM(D10:G10,J10:N10,Q10:U10,X10:AB10,AE10:AH10) -> 0
B11: 23 Arbeitstage | C11: ESSENCE | H11: / | I11: / | O11: / | P11: / | V11: / | W11: / | AC11: / | AD11: / | AI11: =SUM(D11:G11,J11:N11,Q11:U11,X11:AB11,AE11:AH11) -> 0
C12: IDLE | H12: / | I12: / | O12: / | P12: / | V12: / | W12: / | AC12: / | AD12: / | AI12: =SUM(D12:G12,J12:N12,Q12:U12,X12:AB12,AE12:AH12) -> 0
B13: 184 | C13: AREALIGHT | H13: / | I13: / | O13: / | P13: / | V13: / | W13: / | AC13: / | AD13: / | AI13: =SUM(D13:G13,J13:N13,Q13:U13,X13:AB13,AE13:AH13) -> 0
C14: MR ASSIST | D14: 8 | E14: 8 | F14: 8 | G14: 8 | H14: / | I14: / | J14: 8 | K14: 8 | L14: 8 | M14: 8 | N14: 8 | O14: / | P14: / | Q14: 8 | R14: 8 | S14: 8 | T14: 8 | U14: 8 | V14: / | W14: / | X14: U | Y14: U | Z14: U | AA14: U | AB14: U | AC14: / | AD14: / | AE14: 8 | AF14: 8 | AG14: 8 | AH14: 8 | AI14: =SUM(D14:G14,J14:N14,Q14:U14,X14:AB14,AE14:AH14) -> 144
C15: HEATFLUXTEX | H15: / | I15: / | O15: / | P15: / | V15: / | W15: / | AC15: / | AD15: / | AI15: =SUM(D15:G15,J15:N15,Q15:U15,X15:AB15,AE15:AH15) -> 0
C16: TEXWELD | H16: / | I16: / | O16: / | P16: / | V16: / | W16: / | AC16: / | AD16: / | AI16: =SUM(D16:G16,J16:N16,Q16:U16,X16:AB16,AE16:AH16) -> 0
AI17: =SUM(AI9:AI16) -> 144 | AK17: =SUM(AI17,AJ9:AK9) -> 144
B18: August | C18: STIMULATE | E18: / | F18: / | L18: / | M18: / | S18: / | T18: / | Z18: / | AA18: / | AG18: / | AH18: / | AI18: =SUM(D18,G18:K18,N18:R18,U18:Y18,AB18:AF18) -> 0 | AJ18: 40 | AK18: 0
C19: ENKOS | E19: / | F19: / | L19: / | M19: / | S19: / | T19: / | Z19: / | AA19: / | AG19: / | AH19: / | AI19: =SUM(D19,G19:K19,N19:R19,U19:Y19,AB19:AF19) -> 0
B20: 21 Arbeitstage | C20: ESSENCE | E20: / | F20: / | L20: / | M20: / | S20: / | T20: / | Z20: / | AA20: / | AG20: / | AH20: / | AI20: =SUM(D20,G20:K20,N20:R20,U20:Y20,AB20:AF20) -> 0
C21: IDLE | E21: / | F21: / | L21: / | M21: / | S21: / | T21: / | U21: 8 | V21: 8 | W21: 8 | X21: 8 | Y21: 8 | Z21: / | AA21: / | AG21: / | AH21: / | AI21: =SUM(D21,G21:K21,N21:R21,U21:Y21,AB21:AF21) -> 40
B22: 168 | C22: AREALIGHT | E22: / | F22: / | L22: / | M22: / | P22: 8 | Q22: 8 | R22: 8 | S22: / | T22: / | Z22: / | AA22: / | AG22: / | AH22: / | AI22: =SUM(D22,G22:K22,N22:R22,U22:Y22,AB22:AF22) -> 24
C23: MR ASSIST | D23: 8 | E23: / | F23: / | G23: 8 | H23: 8 | I23: 8 | J23: 8 | K23: 8 | L23: / | M23: / | S23: / | T23: / | Z23: / | AA23: / | AB23: U | AC23: U | AD23: U | AE23: U | AF23: U | AG23: / | AH23: / | AI23: =SUM(D23,G23:K23,N23:R23,U23:Y23,AB23:AF23) -> 48
C24: HEATFLUXTEX | E24: / | F24: / | L24: / | M24: / | N24: 8 | O24: 8 | S24: / | T24: / | Z24: / | AA24: / | AG24: / | AH24: / | AI24: =SUM(D24,G24:K24,N24:R24,U24:Y24,AB24:AF24) -> 16
C25: TEXWELD | E25: / | F25: / | L25: / | M25: / | S25: / | T25: / | Z25: / | AA25: / | AG25: / | AH25: / | AI25: =SUM(D25,G25:K25,N25:R25,U25:Y25,AB25:AF25) -> 0
AI26: =SUM(AI18:AI25) -> 128 | AK26: =SUM(AI26,AJ18:AK18) -> 168
B27: September | C27: STIMULATE | D27: U | E27: U | F27: U | G27: U | H27: U | I27: / | J27: / | P27: / | Q27: / | W27: / | X27: / | AD27: / | AE27: / | AI27: =SUM(D27:H27,K27:O27,R27:V27,Y27:AC27,AF27:AG27) -> 0 | AJ27: 40 | AK27: 0
C28: ENKOS | D28: U | E28: U | F28: U | G28: U | H28: U | I28: / | J28: / | P28: / | Q28: / | W28: / | X28: / | AA28: 8 | AB28: 8 | AC28: 8 | AD28: / | AE28: / | AI28: =SUM(D28:H28,K28:O28,R28:V28,Y28:AC28,AF28:AG28) -> 24
B29: 22 Arbeitstage | C29: ESSENCE | D29: U | E29: U | F29: U | G29: U | H29: U | I29: / | J29: / | P29: / | Q29: / | W29: / | X29: / | AD29: / | AE29: / | AI29: =SUM(D29:H29,K29:O29,R29:V29,Y29:AC29,AF29:AG29) -> 0
C30: IDLE | D30: U | E30: U | F30: U | G30: U | H30: U | I30: / | J30: / | P30: / | Q30: / | U30: 8 | V30: 8 | W30: / | X30: / | Y30: 8 | Z30: 8 | AD30: / | AE30: / | AF30: 8 | AG30: 8 | AI30: =SUM(D30:H30,K30:O30,R30:V30,Y30:AC30,AF30:AG30) -> 48
B31: 176 | C31: AREALIGHT | D31: U | E31: U | F31: U | G31: U | H31: U | I31: / | J31: / | P31: / | Q31: / | R31: 8 | S31: 8 | T31: 8 | W31: / | X31: / | AD31: / | AE31: / | AI31: =SUM(D31:H31,K31:O31,R31:V31,Y31:AC31,AF31:AG31) -> 24
C32: MR ASSIST | D32: U | E32: U | F32: U | G32: U | H32: U | I32: / | J32: / | K32: 8 | L32: 8 | M32: 8 | N32: 8 | O32: 8 | P32: / | Q32: / | W32: / | X32: / | AD32: / | AE32: / | AI32: =SUM(D32:H32,K32:O32,R32:V32,Y32:AC32,AF32:AG32) -> 40
C33: HEATFLUXTEX | D33: U | E33: U | F33: U | G33: U | H33: U | I33: / | J33: / | P33: / | Q33: / | W33: / | X33: / | AD33: / | AE33: / | AI33: =SUM(D33:H33,K33:O33,R33:V33,Y33:AC33,AF33:AG33) -> 0
C34: TEXWELD | D34: U | E34: U | F34: U | G34: U | H34: U | I34: / | J34: / | P34: / | Q34: / | W34: / | X34: / | AD34: / | AE34: / | AI34: =SUM(D34:H34,K34:O34,R34:V34,Y34:AC34,AF34:AG34) -> 0
AI35: =SUM(AI27:AI34) -> 136 | AK35: =SUM(AI35,AJ27:AK27) -> 176
B36: Oktober | C36: POLYVETEX | F36: F | G36: / | H36: / | N36: / | O36: / | U36: / | V36: / | AB36: / | AC36: / | AH36: F | AI36: =SUM(D36:E36,I36:M36,P36:T36,W36:AA36,AD36:AG36) -> 0 | AK36: 16
C37: ENKOS | D37: 8 | E37: 8 | F37: F | G37: / | H37: / | I37: 8 | J37: 8 | K37: 8 | L37: 8 | M37: 8 | N37: / | O37: / | U37: / | V37: / | AB37: / | AC37: / | AH37: F | AI37: =SUM(D37:E37,I37:M37,P37:T37,W37:AA37,AD37:AG37) -> 56
B38: 21 Arbeitstage | C38: ESSENCE | F38: F | G38: / | H38: / | N38: / | O38: / | U38: / | V38: / | AB38: / | AC38: / | AH38: F | AI38: =SUM(D38:E38,I38:M38,P38:T38,W38:AA38,AD38:AG38) -> 0
B39: 2 F | C39: IDLE | F39: F | G39: / | H39: / | N39: / | O39: / | U39: / | V39: / | AB39: / | AC39: / | AH39: F | AI39: =SUM(D39:E39,I39:M39,P39:T39,W39:AA39,AD39:AG39) -> 0
B40: 184 | C40: AREALIGHT | F40: F | G40: / | H40: / | N40: / | O40: / | P40: 8 | Q40: 8 | R40: 8 | S40: 8 | T40: 8 | U40: / | V40: / | AB40: / | AC40: / | AD40: 8 | AE40: 8 | AF40: 8 | AG40: 8 | AH40: F | AI40: =SUM(D40:E40,I40:M40,P40:T40,W40:AA40,AD40:AG40) -> 72
C41: FLEXTEXIR | F41: F | G41: / | H41: / | N41: / | O41: / | U41: / | V41: / | AB41: / | AC41: / | AH41: F | AI41: 0
...

Sheet Sabrina F
A1: Jahr | B1: 2025 | F1: / = Wochenende | AA1: 4 Stunden - 24 Dezember
A2: MA: | B2: Mitarbeiter: | C2: Sabrina Froschauer | F2: U=Urlaub | AA2: 4 Stunden - 31 Dezember
F3: K=Krank
F4: KK=Kindkrank
F5: F=Feiertag
D7: Arbeitstag
A8: Monat | B8: Monat | C8: Projekt | D8: 1 | E8: 2 | F8: 3 | G8: 4 | H8: 5 | I8: 6 | J8: 7 | K8: 8 | L8: 9 | M8: 10 | N8: 11 | O8: 12 | P8: 13 | Q8: 14 | R8: 15 | S8: 16 | T8: 17 | U8: 18 | V8: 19 | W8: 20 | X8: 21 | Y8: 22 | Z8: 23 | AA8: 24 | AB8: 25 | AC8: 26 | AD8: 27 | AE8: 28 | AF8: 29 | AG8: 30 | AH8: 31 | AI8: Arbeitsstunden | AJ8: Urlaubstunden | AK8: Feiertag
B9: Juli | C9: STIMULATE | H9: / | I9: / | O9: / | P9: / | V9: / | W9: / | X9: 8 | Y9: 8 | Z9: 8 | AA9: 8 | AB9: 8 | AC9: / | AD9: / | AE9: 8 | AF9: 8 | AG9: 8 | AH9: 8 | AI9: =SUM(D9:G9,J9:N9,Q9:U9,X9:AB9,AE9:AH9) -> 72 | AJ9: 0 | AK9: 0
C10: ENKOS | H10: / | I10: / | O10: / | P10: / | V10: / | W10: / | AC10: / | AD10: / | AI10: =SUM(D10:G10,J10:N10,Q10:U10,X10:AB10,AE10:AH10) -> 0
B11: 23 Arbeitstage | C11: ESSENCE | H11: / | I11: / | O11: / | P11: / | V11: / | W11: / | AC11: / | AD11: / | AI11: =SUM(D11:G11,J11:N11,Q11:U11,X11:AB11,AE11:AH11) -> 0
C12: IDLE | H12: / | I12: / | O12: / | P12: / | V12: / | W12: / | AC12: / | AD12: / | AI12: =SUM(D12:G12,J12:N12,Q12:U12,X12:AB12,AE12:AH12) -> 0
B13: 184 | C13: AREALIGHT | D13: U | E13: U | F13: U | G13: U | H13: / | I13: / | J13: 8 | K13: 8 | L13: 8 | M13: 8 | N13: 8 | O13: / | P13: / | Q13: 8 | R13: K | S13: K | T13: 8 | U13: 8 | V13: / | W13: / | AC13: / | AD13: / | AI13: =SUM(D13:G13,J13:N13,Q13:U13,X13:AB13,AE13:AH13) -> 64
C14: MR ASSIST | H14: / | I14: / | O14: / | P14: / | V14: / | W14: / | AC14: / | AD14: / | AI14: =SUM(D14:G14,J14:N14,Q14:U14,X14:AB14,AE14:AH14) -> 0
C15: HEATFLUXTEX | H15: / | I15: / | O15: / | P15: / | V15: / | W15: / | AC15: / | AD15: / | AI15: =SUM(D15:G15,J15:N15,Q15:U15,X15:AB15,AE15:AH15) -> 0
C16: TEXWELD | H16: / | I16: / | O16: / | P16: / | V16: / | W16: / | AC16: / | AD16: / | AI16: =SUM(D16:G16,J16:N16,Q16:U16,X16:AB16,AE16:AH16) -> 0
AI17: =SUM(AI9:AI16) -> 136 | AK17: =SUM(AI17,AJ9:AK9) -> 136
B18: August | C18: STIMULATE | D18: 8 | E18: / | F18: / | G18: 8 | H18: 8 | I18: 8 | J18: 8 | K18: 8 | L18: / | M18: / | N18: 8 | O18: 8 | P18: 8 | Q18: 8 | R18: 8 | S18: / | T18: / | U18: 8 | V18: 8 | W18: 8 | X18: 8 | Y18: 8 | Z18: / | AA18: / | AB18: 8 | AC18: 4 | AG18: / | AH18: / | AI18: =SUM(D18,G18:K18,N18:R18,U18:Y18,AB18:AF18) -> 140 | AJ18: 0 | AK18: 0
C19: ENKOS | E19: / | F19: / | L19: / | M19: / | S19: / | T19: / | Z19: / | AA19: / | AC19: 4 | AD19: 8 | AE19: 8 | AF19: 8 | AG19: / | AH19: / | AI19: =SUM(D19,G19:K19,N19:R19,U19:Y19,AB19:AF19) -> 28
B20: 21 Arbeitstage | C20: ESSENCE | E20: / | F20: / | L20: / | M20: / | S20: / | T20: / | Z20: / | AA20: / | AG20: / | AH20: / | AI20: =SUM(D20,G20:K20,N20:R20,U20:Y20,AB20:AF20) -> 0
C21: IDLE | E21: / | F21: / | L21: / | M21: / | S21: / | T21: / | Z21: / | AA21: / | AG21: / | AH21: / | AI21: =SUM(D21,G21:K21,N21:R21,U21:Y21,AB21:AF21) -> 0
B22: 168 | C22: AREALIGHT | E22: / | F22: / | L22: / | M22: / | S22: / | T22: / | Z22: / | AA22: / | AG22: / | AH22: / | AI22: =SUM(D22,G22:K22,N22:R22,U22:Y22,AB22:AF22) -> 0
C23: MR ASSIST | E23: / | F23: / | L23: / | M23: / | S23: / | T23: / | Z23: / | AA23: / | AG23: / | AH23: / | AI23: =SUM(D23,G23:K23,N23:R23,U23:Y23,AB23:AF23) -> 0
C24: HEATFLUXTEX | E24: / | F24: / | L24: / | M24: / | S24: / | T24: / | Z24: / | AA24: / | AG24: / | AH24: / | AI24: =SUM(D24,G24:K24,N24:R24,U24:Y24,AB24:AF24) -> 0
C25: TEXWELD | E25: / | F25: / | L25: / | M25: / | S25: / | T25: / | Z25: / | AA25: / | AG25: / | AH25: / | AI25: =SUM(D25,G25:K25,N25:R25,U25:Y25,AB25:AF25) -> 0
AI26: =SUM(AI18:AI25) -> 168 | AK26: =SUM(AI26,AJ18:AK18) -> 168
B27: September | C27: STIMULATE | I27: / | J27: / | K27: U | L27: U | M27: U | N27: U | O27: U | P27: / | Q27: / | W27: / | X27: / | AD27: / | AE27: / | AI27: =SUM(D27:H27,K27:O27,R27:V27,Y27:AC27,AF27:AG27) -> 0 | AJ27: 40 | AK27: 0
C28: ENKOS | I28: / | J28: / | K28: U | L28: U | M28: U | N28: U | O28: U | P28: / | Q28: / | W28: / | X28: / | AD28: / | AE28: / | AI28: =SUM(D28:H28,K28:O28,R28:V28,Y28:AC28,AF28:AG28) -> 0
B29: 22 Arbeitstage | C29: ESSENCE | I29: / | J29: / | K29: U | L29: U | M29: U | N29: U | O29: U | P29: / | Q29: / | W29: / | X29: / | AD29: / | AE29: / | AI29: =SUM(D29:H29,K29:O29,R29:V29,Y29:AC29,AF29:AG29) -> 0
C30: IDLE | I30: / | J30: / | K30: U | L30: U | M30: U | N30: U | O30: U | P30: / | Q30: / | W30: / | X30: / | Y30: 8 | Z30: 8 | AA30: 8 | AB30: 8 | AC30: 8 | AD30: / | AE30: / | AI30: =SUM(D30:H30,K30:O30,R30:V30,Y30:AC30,AF30:AG30) -> 40
B31: 176 | C31: AREALIGHT | D31: 8 | E31: 8 | F31: 8 | G31: 8 | H31: 8 | I31: / | J31: / | K31: U | L31: U | M31: U | N31: U | O31: U | P31: / | Q31: / | R31: 8 | S31: 8 | T31: 8 | U31: 8 | V31: 8 | W31: / | X31: / | AD31: / | AE31: / | AI31: =SUM(D31:H31,K31:O31,R31:V31,Y31:AC31,AF31:AG31) -> 80
C32: MR ASSIST | I32: / | J32: / | K32: U | L32: U | M32: U | N32: U | O32: U | P32: / | Q32: / | W32: / | X32: / | AD32: / | AE32: / | AI32: =SUM(D32:H32,K32:O32,R32:V32,Y32:AC32,AF32:AG32) -> 0
C33: HEATFLUXTEX | I33: / | J33: / | K33: U | L33: U | M33: U | N33: U | O33: U | P33: / | Q33: / | W33: / | X33: / | AD33: / | AE33: / | AI33: =SUM(D33:H33,K33:O33,R33:V33,Y33:AC33,AF33:AG33) -> 0
C34: TEXWELD | I34: / | J34: / | K34: U | L34: U | M34: U | N34: U | O34: U | P34: / | Q34: / | W34: / | X34: / | AD34: / | AE34: / | AI34: =SUM(D34:H34,K34:O34,R34:V34,Y34:AC34,AF34:AG34) -> 0
AI35: =SUM(AI27:AI34) -> 120 | AK35: =SUM(AI35,AJ27:AK27) -> 160
B36: Oktober | C36: POLYVETEX | F36: F | G36: / | H36: / | N36: / | O36: / | U36: / | V36: / | AB36: / | AC36: / | AH36: F | AI36: =SUM(D36:E36,I36:M36,P36:T36,W36:AA36,AD36:AG36) -> 0 | AK36: 16
C37: ENKOS | D37: 8 | E37: 8 | F37: F | G37: / | H37: / | N37: / | O37: / | U37: / | V37: / | AB37: / | AC37: / | AD37: 8 | AE37: 8 | AF37: 8 | AG37: 8 | AH37: F | AI37: =SUM(D37:E37,I37:M37,P37:T37,W37:AA37,AD37:AG37) -> 48
B38: 21 Arbeitstage | C38: ESSENCE | F38: F | G38: / | H38: / | N38: / | O38: / | U38: / | V38: / | AB38: / | AC38: / | AH38: F | AI38: =SUM(D38:E38,I38:M38,P38:T38,W38:AA38,AD38:AG38) -> 0
B39: 2 F | C39: IDLE | F39: F | G39: / | H39: / | I39: 8 | J39: 8 | K39: 8 | L39: 8 | M39: 8 | N39: / | O39: / | U39: / | V39: / | AB39: / | AC39: / | AH39: F | AI39: =SUM(D39:E39,I39:M39,P39:T39,W39:AA39,AD39:AG39) -> 40
B40: 184 | C40: AREALIGHT | F40: F | G40: / | H40: / | N40: / | O40: / | P40: 8 | Q40: 8 | R40: 8 | S40: 8 | T40: 8 | U40: / | V40: / | W40: 8 | X40: 8 | Y40: 8 | Z40: 8 | AA40: 8 | AB40: / | AC40: / | AH40: F | AI40: =SUM(D40:E40,I40:M40,P40:T40,W40:AA40,AD40:AG40) -> 80
C41: FLEXTEXIR | F41: F | G41: / | H41: / | N41: / | O41: / | U41: / | V41: / | AB41: / | AC41: / | AH41: F | AI41: 0
...

Sheet Karen JT
A1: Jahr | B1: 2025 | F1: / = Wochenende | AA1: 4 Stunden - 24 Dezember
A2: MA: | B2: Mitarbeiter: | C2: Karen Jimenez Taube | F2: U=Urlaub | AA2: 4 Stunden - 31 Dezember
F3: K=Krank
F4: KK=Kindkrank
F5: F=Feiertag
D7: Arbeitstag
A8: Monat | B8: Monat | C8: Projekt | D8: 1 | E8: 2 | F8: 3 | G8: 4 | H8: 5 | I8: 6 | J8: 7 | K8: 8 | L8: 9 | M8: 10 | N8: 11 | O8: 12 | P8: 13 | Q8: 14 | R8: 15 | S8: 16 | T8: 17 | U8: 18 | V8: 19 | W8: 20 | X8: 21 | Y8: 22 | Z8: 23 | AA8: 24 | AB8: 25 | AC8: 26 | AD8: 27 | AE8: 28 | AF8: 29 | AG8: 30 | AH8: 31 | AI8: Arbeitsstunden | AJ8: Urlaubstunden | AK8: Feiertag | AL8: K
B9: Juli | C9: STIMULATE | H9: / | I9: / | O9: / | P9: / | V9: / | W9: / | AC9: / | AD9: / | AI9: =SUM(D9:G9,J9:N9,Q9:U9,X9:AB9,AE9:AH9) -> 0 | AJ9: 0 | AK9: 0
C10: ENKOS | H10: / | I10: / | O10: / | P10: / | V10: / | W10: / | AC10: / | AD10: / | AI10: =SUM(D10:G10,J10:N10,Q10:U10,X10:AB10,AE10:AH10) -> 0
B11: 23 Arbeitstage | C11: ESSENCE | H11: / | I11: / | O11: / | P11: / | V11: / | W11: / | AC11: / | AD11: / | AI11: =SUM(D11:G11,J11:N11,Q11:U11,X11:AB11,AE11:AH11) -> 0
C12: IDLE | H12: / | I12: / | O12: / | P12: / | V12: / | W12: / | AC12: / | AD12: / | AI12: =SUM(D12:G12,J12:N12,Q12:U12,X12:AB12,AE12:AH12) -> 0
B13: 184 | C13: AREALIGHT | D13: 5 | E13: 5 | F13: 5 | G13: 5 | H13: / | I13: / | J13: 5 | K13: 5 | L13: 5 | M13: 5 | N13: 5 | O13: / | P13: / | Q13: 5 | R13: 5 | S13: 5 | T13: 5 | U13: 5 | V13: / | W13: / | X13: U | Y13: U | Z13: U | AA13: U | AB13: U | AC13: / | AD13: / | AE13: U | AF13: U | AG13: U | AH13: U | AI13: =SUM(D13:G13,J13:N13,Q13:U13,X13:AB13,AE13:AH13) -> 70
C14: MR ASSIST | H14: / | I14: / | O14: / | P14: / | V14: / | W14: / | AC14: / | AD14: / | AI14: =SUM(D14:G14,J14:N14,Q14:U14,X14:AB14,AE14:AH14) -> 0
C15: HEATFLUXTEX | H15: / | I15: / | O15: / | P15: / | V15: / | W15: / | AC15: / | AD15: / | AI15: =SUM(D15:G15,J15:N15,Q15:U15,X15:AB15,AE15:AH15) -> 0
C16: TEXWELD | H16: / | I16: / | O16: / | P16: / | V16: / | W16: / | AC16: / | AD16: / | AI16: =SUM(D16:G16,J16:N16,Q16:U16,X16:AB16,AE16:AH16) -> 0
AI17: =SUM(AI9:AI16) -> 70 | AK17: =SUM(AI17,AJ9:AK9) -> 70
B18: August | C18: STIMULATE | E18: / | F18: / | L18: / | M18: / | S18: / | T18: / | Z18: / | AA18: / | AG18: / | AH18: / | AI18: =SUM(D18,G18:K18,N18:R18,U18:Y18,AB18:AF18) -> 0 | AJ18: 0 | AK18: 0
C19: ENKOS | E19: / | F19: / | L19: / | M19: / | S19: / | T19: / | Z19: / | AA19: / | AG19: / | AH19: / | AI19: =SUM(D19,G19:K19,N19:R19,U19:Y19,AB19:AF19) -> 0
B20: 21 Arbeitstage | C20: ESSENCE | E20: / | F20: / | L20: / | M20: / | S20: / | T20: / | Z20: / | AA20: / | AG20: / | AH20: / | AI20: =SUM(D20,G20:K20,N20:R20,U20:Y20,AB20:AF20) -> 0
C21: IDLE | E21: / | F21: / | L21: / | M21: / | S21: / | T21: / | Z21: / | AA21: / | AG21: / | AH21: / | AI21: =SUM(D21,G21:K21,N21:R21,U21:Y21,AB21:AF21) -> 0
B22: 168 | C22: AREALIGHT | D22: U | E22: / | F22: / | G22: 5 | H22: 5 | I22: 5 | J22: 5 | K22: 5 | L22: / | M22: / | N22: U | O22: 5 | P22: 5 | Q22: 5 | R22: 5 | S22: / | T22: / | U22: 5 | V22: 5 | W22: 5 | X22: 5 | Y22: 5 | Z22: / | AA22: / | AB22: 5 | AC22: 5 | AD22: 5 | AE22: 5 | AF22: 5 | AG22: / | AH22: / | AI22: =SUM(D22,G22:K22,N22:R22,U22:Y22,AB22:AF22) -> 95
C23: MR ASSIST | E23: / | F23: / | L23: / | M23: / | S23: / | T23: / | Z23: / | AA23: / | AG23: / | AH23: / | AI23: =SUM(D23,G23:K23,N23:R23,U23:Y23,AB23:AF23) -> 0
C24: HEATFLUXTEX | E24: / | F24: / | L24: / | M24: / | S24: / | T24: / | Z24: / | AA24: / | AG24: / | AH24: / | AI24: =SUM(D24,G24:K24,N24:R24,U24:Y24,AB24:AF24) -> 0
C25: TEXWELD | E25: / | F25: / | L25: / | M25: / | S25: / | T25: / | Z25: / | AA25: / | AG25: / | AH25: / | AI25: =SUM(D25,G25:K25,N25:R25,U25:Y25,AB25:AF25) -> 0
AI26: =SUM(AI18:AI25) -> 95 | AK26: =SUM(AI26,AJ18:AK18) -> 95
B27: September | C27: STIMULATE | E27: K | F27: K | G27: K | I27: / | J27: / | P27: / | Q27: / | W27: / | X27: / | AD27: / | AE27: / | AI27: =SUM(D27:H27,K27:O27,R27:V27,Y27:AC27,AF27:AG27) -> 0 | AJ27: 0 | AK27: 0 | AL27: 15
C28: ENKOS | E28: K | F28: K | G28: K | I28: / | J28: / | P28: / | Q28: / | W28: / | X28: / | AD28: / | AE28: / | AI28: =SUM(D28:H28,K28:O28,R28:V28,Y28:AC28,AF28:AG28) -> 0
B29: 22 Arbeitstage | C29: ESSENCE | E29: K | F29: K | G29: K | I29: / | J29: / | P29: / | Q29: / | W29: / | X29: / | AD29: / | AE29: / | AI29: =SUM(D29:H29,K29:O29,R29:V29,Y29:AC29,AF29:AG29) -> 0
C30: IDLE | E30: K | F30: K | G30: K | I30: / | J30: / | P30: / | Q30: / | W30: / | X30: / | AD30: / | AE30: / | AI30: =SUM(D30:H30,K30:O30,R30:V30,Y30:AC30,AF30:AG30) -> 0
B31: 176 | C31: AREALIGHT | D31: 5 | E31: K | F31: K | G31: K | H31: 5 | I31: / | J31: / | K31: 5 | L31: 5 | M31: 5 | N31: 5 | O31: 5 | P31: / | Q31: / | R31: 5 | S31: 5 | T31: 5 | U31: 5 | V31: 5 | W31: / | X31: / | Y31: 5 | Z31: 5 | AA31: 5 | AB31: 5 | AC31: 5 | AD31: / | AE31: / | AF31: 5 | AG31: 5 | AI31: =SUM(D31:H31,K31:O31,R31:V31,Y31:AC31,AF31:AG31) -> 95
C32: MR ASSIST | E32: K | F32: K | G32: K | I32: / | J32: / | P32: / | Q32: / | W32: / | X32: / | AD32: / | AE32: / | AI32: =SUM(D32:H32,K32:O32,R32:V32,Y32:AC32,AF32:AG32) -> 0
C33: HEATFLUXTEX | E33: K | F33: K | G33: K | I33: / | J33: / | P33: / | Q33: / | W33: / | X33: / | AD33: / | AE33: / | AI33: =SUM(D33:H33,K33:O33,R33:V33,Y33:AC33,AF33:AG33) -> 0
C34: TEXWELD | E34: K | F34: K | G34: K | I34: / | J34: / | P34: / | Q34: / | W34: / | X34: / | AD34: / | AE34: / | AI34: =SUM(D34:H34,K34:O34,R34:V34,Y34:AC34,AF34:AG34) -> 0
AI35: =SUM(AI27:AI34) -> 95 | AM35: =SUM(AI35,AJ27:AL27) -> 110
B36: Oktober | C36: POLYVETEX | F36: F | G36: / | H36: / | N36: / | O36: / | P36: U | Q36: U | R36: U | S36: U | T36: U | U36: / | V36: / | AB36: / | AC36: / | AH36: F | AI36: =SUM(D36:E36,I36:M36,P36:T36,W36:AA36,AD36:AG36) -> 0 | AJ36: 25 | AK36: 10
C37: ENKOS | F37: F | G37: / | H37: / | N37: / | O37: / | P37: U | Q37: U | R37: U | S37: U | T37: U | U37: / | V37: / | AB37: / | AC37: / | AH37: F | AI37: =SUM(D37:E37,I37:M37,P37:T37,W37:AA37,AD37:AG37) -> 0
B38: 21 Arbeitstage | C38: ESSENCE | F38: F | G38: / | H38: / | N38: / | O38: / | P38: U | Q38: U | R38: U | S38: U | T38: U | U38: / | V38: / | AB38: / | AC38: / | AH38: F | AI38: =SUM(D38:E38,I38:M38,P38:T38,W38:AA38,AD38:AG38) -> 0
B39: 2 F | C39: IDLE | F39: F | G39: / | H39: / | N39: / | O39: / | P39: U | Q39: U | R39: U | S39: U | T39: U | U39: / | V39: / | AB39: / | AC39: / | AH39: F | AI39: =SUM(D39:E39,I39:M39,P39:T39,W39:AA39,AD39:AG39) -> 0
B40: 184 | C40: AREALIGHT | D40: 5 | E40: 5 | F40: F | G40: / | H40: / | I40: 5 | J40: 5 | K40: 5 | L40: 5 | M40: 5 | N40: / | O40: / | P40: U | Q40: U | R40: U | S40: U | T40: U | U40: / | V40: / | W40: 5 | X40: 5 | Y40: 5 | Z40: 5 | AA40: 5 | AB40: / | AC40: / | AD40: 5 | AE40: 5 | AF40: 5 | AG40: 5 | AH40: F | AI40: =SUM(D40:E40,I40:M40,P40:T40,W40:AA40,AD40:AG40) -> 80
C41: FLEXTEXIR | F41: F | G41: / | H41: / | N41: / | O41: / | P41: U | Q41: U | R41: U | S41: U | T41: U | U41: / | V41: / | AB41: / | AC41: / | AH41: F | AI41: 0
...

Sheet Ron J
A1: Jahr | B1: 2025 | F1: / = Wochenende | AA1: 4 Stunden - 24 Dezember
A2: MA: | B2: Mitarbeiter: | C2: Ron Jacob | F2: U=Urlaub | AA2: 4 Stunden - 31 Dezember
F3: K=Krank
F4: KK=Kindkrank
F5: F=Feiertag
F6: X= freier Tag von Ron (4-Tage-Woche)
D7: Arbeitstag
A8: Monat | B8: Monat | C8: Projekt | D8: 1 | E8: 2 | F8: 3 | G8: 4 | H8: 5 | I8: 6 | J8: 7 | K8: 8 | L8: 9 | M8: 10 | N8: 11 | O8: 12 | P8: 13 | Q8: 14 | R8: 15 | S8: 16 | T8: 17 | U8: 18 | V8: 19 | W8: 20 | X8: 21 | Y8: 22 | Z8: 23 | AA8: 24 | AB8: 25 | AC8: 26 | AD8: 27 | AE8: 28 | AF8: 29 | AG8: 30 | AH8: 31 | AI8: Arbeitsstunden | AJ8: Urlaubstunden | AK8: Feiertag
B9: Juli | C9: STIMULATE | H9: / | I9: / | O9: / | P9: / | V9: / | W9: / | AC9: / | AD9: / | AI9: =SUM(D9:G9,J9:N9,Q9:U9,X9:AB9,AE9:AH9) -> 0 | AJ9: 64 | AK9: 0
C10: ENKOS | H10: / | I10: / | O10: / | P10: / | V10: / | W10: / | AC10: / | AD10: / | AI10: =SUM(D10:G10,J10:N10,Q10:U10,X10:AB10,AE10:AH10) -> 0
B11: 23 Arbeitstage | C11: ESSENCE | H11: / | I11: / | O11: / | P11: / | V11: / | W11: / | AC11: / | AD11: / | AI11: =SUM(D11:G11,J11:N11,Q11:U11,X11:AB11,AE11:AH11) -> 0
C12: IDLE | H12: / | I12: / | O12: / | P12: / | V12: / | W12: / | AC12: / | AD12: / | AI12: =SUM(D12:G12,J12:N12,Q12:U12,X12:AB12,AE12:AH12) -> 0
B13: 184 | C13: AREALIGHT | H13: / | I13: / | O13: / | P13: / | V13: / | W13: / | AC13: / | AD13: / | AI13: =SUM(D13:G13,J13:N13,Q13:U13,X13:AB13,AE13:AH13) -> 0
C14: MR ASSIST | D14: 8 | E14: 8 | F14: X | G14: 8 | H14: / | I14: / | J14: U | K14: U | L14: U | M14: U | N14: X | O14: / | P14: / | Q14: U | R14: U | S14: U | T14: U | U14: X | V14: / | W14: / | X14: 8 | Y14: 8 | Z14: 8 | AA14: 8 | AB14: x | AC14: / | AD14: / | AE14: 8 | AF14: 8 | AG14: 8 | AH14: 8 | AI14: =SUM(D14:G14,J14:N14,Q14:U14,X14:AB14,AE14:AH14) -> 88
C15: HEATFLUXTEX | H15: / | I15: / | O15: / | P15: / | V15: / | W15: / | AC15: / | AD15: / | AI15: =SUM(D15:G15,J15:N15,Q15:U15,X15:AB15,AE15:AH15) -> 0
C16: TEXWELD | H16: / | I16: / | O16: / | P16: / | V16: / | W16: / | AC16: / | AD16: / | AI16: =SUM(D16:G16,J16:N16,Q16:U16,X16:AB16,AE16:AH16) -> 0
AI17: =SUM(AI9:AI16) -> 88 | AK17: =SUM(AI17,AJ9:AK9) -> 152
B18: August | C18: STIMULATE | E18: / | F18: / | L18: / | M18: / | S18: / | T18: / | Z18: / | AA18: / | AG18: / | AH18: / | AI18: =SUM(D18,G18:K18,N18:R18,U18:Y18,AB18:AF18) -> 0 | AJ18: 0 | AK18: 0
C19: ENKOS | E19: / | F19: / | G19: 8 | H19: 8 | I19: 8 | J19: 8 | L19: / | M19: / | N19: 8 | O19: 8 | S19: / | T19: / | Z19: / | AA19: / | AG19: / | AH19: / | AI19: =SUM(D19,G19:K19,N19:R19,U19:Y19,AB19:AF19) -> 48
B20: 21 Arbeitstage | C20: ESSENCE | E20: / | F20: / | L20: / | M20: / | S20: / | T20: / | U20: 8 | V20: 8 | W20: 8 | X20: 8 | Z20: / | AA20: / | AB20: 8 | AC20: 8 | AD20: 8 | AE20: 8 | AG20: / | AH20: / | AI20: =SUM(D20,G20:K20,N20:R20,U20:Y20,AB20:AF20) -> 64
C21: IDLE | E21: / | F21: / | L21: / | M21: / | S21: / | T21: / | Z21: / | AA21: / | AG21: / | AH21: / | AI21: =SUM(D21,G21:K21,N21:R21,U21:Y21,AB21:AF21) -> 0
B22: 168 | C22: AREALIGHT | E22: / | F22: / | L22: / | M22: / | S22: / | T22: / | Z22: / | AA22: / | AG22: / | AH22: / | AI22: =SUM(D22,G22:K22,N22:R22,U22:Y22,AB22:AF22) -> 0
C23: MR ASSIST | D23: x | E23: / | F23: / | K23: x | L23: / | M23: / | P23: 8 | Q23: 8 | R23: x | S23: / | T23: / | Y23: X | Z23: / | AA23: / | AF23: X | AG23: / | AH23: / | AI23: =SUM(D23,G23:K23,N23:R23,U23:Y23,AB23:AF23) -> 16
C24: HEATFLUXTEX | E24: / | F24: / | L24: / | M24: / | S24: / | T24: / | Z24: / | AA24: / | AG24: / | AH24: / | AI24: =SUM(D24,G24:K24,N24:R24,U24:Y24,AB24:AF24) -> 0
C25: TEXWELD | E25: / | F25: / | L25: / | M25: / | S25: / | T25: / | Z25: / | AA25: / | AG25: / | AH25: / | AI25: =SUM(D25,G25:K25,N25:R25,U25:Y25,AB25:AF25) -> 0
AI26: =SUM(AI18:AI25) -> 128 | AK26: =SUM(AI26,AJ18:AK18) -> 128
B27: September | C27: STIMULATE | H27: x | I27: / | J27: / | O27: x | P27: / | Q27: / | V27: x | W27: / | X27: / | AC27: x | AD27: / | AE27: / | AI27: =SUM(D27:H27,K27:O27,R27:V27,Y27:AC27,AF27:AG27) -> 0 | AJ27: 0 | AK27: 0
C28: ENKOS | H28: x | I28: / | J28: / | O28: x | P28: / | Q28: / | V28: x | W28: / | X28: / | AC28: x | AD28: / | AE28: / | AF28: 8 | AG28: 8 | AI28: =SUM(D28:H28,K28:O28,R28:V28,Y28:AC28,AF28:AG28) -> 16
B29: 22 Arbeitstage | C29: ESSENCE | H29: x | I29: / | J29: / | O29: x | P29: / | Q29: / | V29: x | W29: / | X29: / | Y29: 8 | Z29: 8 | AA29: 8 | AB29: 8 | AC29: x | AD29: / | AE29: / | AI29: =SUM(D29:H29,K29:O29,R29:V29,Y29:AC29,AF29:AG29) -> 32
C30: IDLE | H30: x | I30: / | J30: / | O30: x | P30: / | Q30: / | V30: x | W30: / | X30: / | AC30: x | AD30: / | AE30: / | AI30: =SUM(D30:H30,K30:O30,R30:V30,Y30:AC30,AF30:AG30) -> 0
B31: 176 | C31: AREALIGHT | H31: x | I31: / | J31: / | O31: x | P31: / | Q31: / | V31: x | W31: / | X31: / | AC31: x | AD31: / | AE31: / | AI31: =SUM(D31:H31,K31:O31,R31:V31,Y31:AC31,AF31:AG31) -> 0
C32: MR ASSIST | H32: x | I32: / | J32: / | O32: x | P32: / | Q32: / | V32: x | W32: / | X32: / | AC32: x | AD32: / | AE32: / | AI32: =SUM(D32:H32,K32:O32,R32:V32,Y32:AC32,AF32:AG32) -> 0
C33: HEATFLUXTEX | D33: 8 | E33: 8 | F33: 8 | G33: 8 | H33: x | I33: / | J33: / | K33: 8 | L33: 8 | M33: 8 | N33: 8 | O33: x | P33: / | Q33: / | R33: 8 | S33: 8 | T33: 8 | U33: 8 | V33: x | W33: / | X33: / | AC33: x | AD33: / | AE33: / | AI33: =SUM(D33:H33,K33:O33,R33:V33,Y33:AC33,AF33:AG33) -> 96
C34: TEXWELD | H34: x | I34: / | J34: / | O34: x | P34: / | Q34: / | V34: x | W34: / | X34: / | AC34: x | AD34: / | AE34: / | AI34: =SUM(D34:H34,K34:O34,R34:V34,Y34:AC34,AF34:AG34) -> 0
AI35: =SUM(AI27:AI34) -> 144 | AK35: =SUM(AI35,AJ27:AK27) -> 144
B36: Oktober | C36: POLYVETEX | F36: F | G36: / | H36: / | I36: U | J36: U | K36: U | L36: U | M36: x | N36: / | O36: / | T36: x | U36: / | V36: / | AA36: x | AB36: / | AC36: / | AH36: F | AI36: =SUM(D36:E36,I36:M36,P36:T36,W36:AA36,AD36:AG36) -> 0 | AJ36: 32 | AK36: 16
C37: ENKOS | F37: F | G37: / | H37: / | I37: U | J37: U | K37: U | L37: U | M37: x | N37: / | O37: / | T37: x | U37: / | V37: / | AA37: x | AB37: / | AC37: / | AH37: F | AI37: =SUM(D37:E37,I37:M37,P37:T37,W37:AA37,AD37:AG37) -> 0
B38: 22 Arbeitstage | C38: ESSENCE | F38: F | G38: / | H38: / | I38: U | J38: U | K38: U | L38: U | M38: x | N38: / | O38: / | T38: x | U38: / | V38: / | AA38: x | AB38: / | AC38: / | AH38: F | AI38: =SUM(D38:E38,I38:M38,P38:T38,W38:AA38,AD38:AG38) -> 0
B39: 2 F | C39: IDLE | F39: F | G39: / | H39: / | I39: U | J39: U | K39: U | L39: U | M39: x | N39: / | O39: / | T39: x | U39: / | V39: / | AA39: x | AB39: / | AC39: / | AH39: F | AI39: =SUM(D39:E39,I39:M39,P39:T39,W39:AA39,AD39:AG39) -> 0
B40: 184 | C40: AREALIGHT | F40: F | G40: / | H40: / | I40: U | J40: U | K40: U | L40: U | M40: x | N40: / | O40: / | T40: x | U40: / | V40: / | AA40: x | AB40: / | AC40: / | AH40: F | AI40: =SUM(D40:E40,I40:M40,P40:T40,W40:AA40,AD40:AG40) -> 0
...

Sheet Lucas H
A1: Jahr | B1: 2025 | F1: / = Wochenende | AA1: 4 Stunden - 24 Dezember
A2: MA: | B2: Mitarbeiter: | C2: Lucas Hauser | F2: U=Urlaub | AA2: 4 Stunden - 31 Dezember
F3: K=Krank
F4: KK=Kindkrank
F5: F=Feiertag
D7: Arbeitstag
A8: Monat | B8: Monat | C8: Projekt | D8: 1 | E8: 2 | F8: 3 | G8: 4 | H8: 5 | I8: 6 | J8: 7 | K8: 8 | L8: 9 | M8: 10 | N8: 11 | O8: 12 | P8: 13 | Q8: 14 | R8: 15 | S8: 16 | T8: 17 | U8: 18 | V8: 19 | W8: 20 | X8: 21 | Y8: 22 | Z8: 23 | AA8: 24 | AB8: 25 | AC8: 26 | AD8: 27 | AE8: 28 | AF8: 29 | AG8: 30 | AH8: 31 | AI8: Arbeitsstunden | AJ8: Urlaubstunden | AK8: Feiertag
B9: Juli | C9: STIMULATE | H9: / | I9: / | O9: / | P9: / | V9: / | W9: / | AC9: / | AD9: / | AI9: =SUM(D9:G9,J9:N9,Q9:U9,X9:AB9,AE9:AH9) -> 0 | AJ9: 0 | AK9: 0
C10: ENKOS | H10: / | I10: / | O10: / | P10: / | V10: / | W10: / | AC10: / | AD10: / | AI10: =SUM(D10:G10,J10:N10,Q10:U10,X10:AB10,AE10:AH10) -> 0
B11: 23 Arbeitstage | C11: ESSENCE | H11: / | I11: / | O11: / | P11: / | S11: 8 | T11: 8 | U11: 8 | V11: / | W11: / | X11: 8 | Y11: 8 | Z11: 8 | AA11: 8 | AB11: 8 | AC11: / | AD11: / | AE11: 8 | AF11: 8 | AG11: 8 | AH11: 8 | AI11: =SUM(D11:G11,J11:N11,Q11:U11,X11:AB11,AE11:AH11) -> 96
C12: IDLE | H12: / | I12: / | O12: / | P12: / | V12: / | W12: / | AC12: / | AD12: / | AI12: =SUM(D12:G12,J12:N12,Q12:U12,X12:AB12,AE12:AH12) -> 0
B13: 184 | C13: AREALIGHT | D13: 8 | E13: 8 | F13: 8 | G13: 8 | H13: / | I13: / | J13: 8 | K13: 8 | L13: 8 | M13: 8 | N13: U | O13: / | P13: / | Q13: 8 | R13: 8 | V13: / | W13: / | AC13: / | AD13: / | AI13: =SUM(D13:G13,J13:N13,Q13:U13,X13:AB13,AE13:AH13) -> 80
C14: MR ASSIST | H14: / | I14: / | O14: / | P14: / | V14: / | W14: / | AC14: / | AD14: / | AI14: =SUM(D14:G14,J14:N14,Q14:U14,X14:AB14,AE14:AH14) -> 0
C15: HEATFLUXTEX | H15: / | I15: / | O15: / | P15: / | V15: / | W15: / | AC15: / | AD15: / | AI15: =SUM(D15:G15,J15:N15,Q15:U15,X15:AB15,AE15:AH15) -> 0
C16: TEXWELD | H16: / | I16: / | O16: / | P16: / | V16: / | W16: / | AC16: / | AD16: / | AI16: =SUM(D16:G16,J16:N16,Q16:U16,X16:AB16,AE16:AH16) -> 0
AI17: =SUM(AI9:AI16) -> 176 | AK17: =SUM(AI17,AJ9:AK9) -> 176
B18: August | C18: STIMULATE | E18: / | F18: / | L18: / | M18: / | S18: / | T18: / | Z18: / | AA18: / | AG18: / | AH18: / | AI18: =SUM(D18,G18:K18,N18:R18,U18:Y18,AB18:AF18) -> 0 | AJ18: 0 | AK18: 0
C19: ENKOS | E19: / | F19: / | L19: / | M19: / | R19: 8 | S19: / | T19: / | U19: 8 | V19: 8 | W19: 8 | X19: 8 | Z19: / | AA19: / | AG19: / | AH19: / | AI19: =SUM(D19,G19:K19,N19:R19,U19:Y19,AB19:AF19) -> 40
B20: 21 Arbeitstage | C20: ESSENCE | E20: / | F20: / | L20: / | M20: / | S20: / | T20: / | Z20: / | AA20: / | AB20: 8 | AC20: 8 | AD20: 8 | AE20: 8 | AF20: 8 | AG20: / | AH20: / | AI20: =SUM(D20,G20:K20,N20:R20,U20:Y20,AB20:AF20) -> 40
C21: IDLE | E21: / | F21: / | L21: / | M21: / | S21: / | T21: / | Z21: / | AA21: / | AG21: / | AH21: / | AI21: =SUM(D21,G21:K21,N21:R21,U21:Y21,AB21:AF21) -> 0
B22: 168 | C22: AREALIGHT | D22: 8 | E22: / | F22: / | G22: 8 | H22: 8 | I22: 8 | J22: 8 | K22: 8 | L22: / | M22: / | N22: 8 | O22: 8 | P22: 8 | Q22: 8 | S22: / | T22: / | Y22: U | Z22: / | AA22: / | AG22: / | AH22: / | AI22: =SUM(D22,G22:K22,N22:R22,U22:Y22,AB22:AF22) -> 80
C23: MR ASSIST | E23: / | F23: / | L23: / | M23: / | S23: / | T23: / | Z23: / | AA23: / | AG23: / | AH23: / | AI23: =SUM(D23,G23:K23,N23:R23,U23:Y23,AB23:AF23) -> 0
C24: HEATFLUXTEX | E24: / | F24: / | L24: / | M24: / | S24: / | T24: / | Z24: / | AA24: / | AG24: / | AH24: / | AI24: =SUM(D24,G24:K24,N24:R24,U24:Y24,AB24:AF24) -> 0
C25: TEXWELD | E25: / | F25: / | L25: / | M25: / | S25: / | T25: / | Z25: / | AA25: / | AG25: / | AH25: / | AI25: =SUM(D25,G25:K25,N25:R25,U25:Y25,AB25:AF25) -> 0
AI26: =SUM(AI18:AI25) -> 160 | AK26: =SUM(AI26,AJ18:AK18) -> 160
B27: September | C27: STIMULATE | I27: / | J27: / | P27: / | Q27: / | V27: U | W27: / | X27: / | Y27: U | Z27: U | AA27: U | AB27: U | AC27: U | AD27: / | AE27: / | AI27: =SUM(D27:H27,K27:O27,R27:V27,Y27:AC27,AF27:AG27) -> 0 | AJ27: 48 | AK27: 0
C28: ENKOS | I28: / | J28: / | P28: / | Q28: / | R28: 8 | S28: 8 | T28: 8 | U28: 8 | V28: U | W28: / | X28: / | Y28: U | Z28: U | AA28: U | AB28: U | AC28: U | AD28: / | AE28: / | AF28: 8 | AG28: 8 | AI28: =SUM(D28:H28,K28:O28,R28:V28,Y28:AC28,AF28:AG28) -> 48
B29: 22 Arbeitstage | C29: ESSENCE | D29: 8 | E29: 8 | F29: 8 | G29: 8 | H29: 8 | I29: / | J29: / | K29: 8 | L29: 8 | P29: / | Q29: / | V29: U | W29: / | X29: / | Y29: U | Z29: U | AA29: U | AB29: U | AC29: U | AD29: / | AE29: / | AI29: =SUM(D29:H29,K29:O29,R29:V29,Y29:AC29,AF29:AG29) -> 56
C30: IDLE | I30: / | J30: / | P30: / | Q30: / | V30: U | W30: / | X30: / | Y30: U | Z30: U | AA30: U | AB30: U | AC30: U | AD30: / | AE30: / | AI30: =SUM(D30:H30,K30:O30,R30:V30,Y30:AC30,AF30:AG30) -> 0
B31: 176 | C31: AREALIGHT | I31: / | J31: / | P31: / | Q31: / | V31: U | W31: / | X31: / | Y31: U | Z31: U | AA31: U | AB31: U | AC31: U | AD31: / | AE31: / | AI31: =SUM(D31:H31,K31:O31,R31:V31,Y31:AC31,AF31:AG31) -> 0
C32: MR ASSIST | I32: / | J32: / | M32: 8 | N32: 8 | O32: 8 | P32: / | Q32: / | V32: U | W32: / | X32: / | Y32: U | Z32: U | AA32: U | AB32: U | AC32: U | AD32: / | AE32: / | AI32: =SUM(D32:H32,K32:O32,R32:V32,Y32:AC32,AF32:AG32) -> 24
C33: HEATFLUXTEX | I33: / | J33: / | P33: / | Q33: / | V33: U | W33: / | X33: / | Y33: U | Z33: U | AA33: U | AB33: U | AC33: U | AD33: / | AE33: / | AI33: =SUM(D33:H33,K33:O33,R33:V33,Y33:AC33,AF33:AG33) -> 0
C34: TEXWELD | I34: / | J34: / | P34: / | Q34: / | V34: U | W34: / | X34: / | Y34: U | Z34: U | AA34: U | AB34: U | AC34: U | AD34: / | AE34: / | AI34: =SUM(D34:H34,K34:O34,R34:V34,Y34:AC34,AF34:AG34) -> 0
AI35: =SUM(AI27:AI34) -> 128 | AK35: =SUM(AI35,AJ27:AK27) -> 176
B36: Oktober | C36: POLYVETEX | F36: F | G36: / | H36: / | N36: / | O36: / | U36: / | V36: / | AB36: / | AC36: / | AH36: F | AI36: =SUM(D36:E36,I36:M36,P36:T36,W36:AA36,AD36:AG36) -> 0 | AK36: 16
C37: ENKOS | F37: F | G37: / | H37: / | N37: / | O37: / | P37: 8 | Q37: 8 | R37: 8 | S37: 8 | T37: 8 | U37: / | V37: / | AB37: / | AC37: / | AD37: 8 | AE37: 8 | AF37: 8 | AG37: 8 | AH37: F | AI37: =SUM(D37:E37,I37:M37,P37:T37,W37:AA37,AD37:AG37) -> 72
B38: 22 Arbeitstage | C38: ESSENCE | D38: 8 | E38: 8 | F38: F | G38: / | H38: / | I38: 8 | J38: 8 | K38: 8 | L38: 8 | M38: 8 | N38: / | O38: / | U38: / | V38: / | AB38: / | AC38: / | AH38: F | AI38: =SUM(D38:E38,I38:M38,P38:T38,W38:AA38,AD38:AG38) -> 56
B39: 2 F | C39: IDLE | F39: F | G39: / | H39: / | N39: / | O39: / | U39: / | V39: / | AB39: / | AC39: / | AH39: F | AI39: =SUM(D39:E39,I39:M39,P39:T39,W39:AA39,AD39:AG39) -> 0
B40: 184 | C40: AREALIGHT | F40: F | G40: / | H40: / | N40: / | O40: / | U40: / | V40: / | W40: 8 | X40: 8 | Y40: 8 | Z40: 8 | AA40: 8 | AB40: / | AC40: / | AH40: F | AI40: =SUM(D40:E40,I40:M40,P40:T40,W40:AA40,AD40:AG40) -> 40
C41: FLEXTEXIR | F41: F | G41: / | H41: / | N41: / | O41: / | U41: / | V41: / | AB41: / | AC41: / | AH41: F | AI41: 0
...

Sheet Mayuresh P
A1: Jahr | B1: 2025 | F1: / = Wochenende | AA1: 4 Stunden - 24 Dezember
A2: MA: | B2: Mitarbeiter: | C2: Thomas Juhlemann | F2: U=Urlaub | AA2: 4 Stunden - 31 Dezember
F3: K=Krank
F4: KK=Kindkrank
F5: F=Feiertag
D7: Arbeitstag
A8: Monat | B8: Monat | C8: Projekt | D8: 1 | E8: 2 | F8: 3 | G8: 4 | H8: 5 | I8: 6 | J8: 7 | K8: 8 | L8: 9 | M8: 10 | N8: 11 | O8: 12 | P8: 13 | Q8: 14 | R8: 15 | S8: 16 | T8: 17 | U8: 18 | V8: 19 | W8: 20 | X8: 21 | Y8: 22 | Z8: 23 | AA8: 24 | AB8: 25 | AC8: 26 | AD8: 27 | AE8: 28 | AF8: 29 | AG8: 30 | AH8: 31 | AI8: Arbeitsstunden | AJ8: Urlaubstunden | AK8: Feiertag
B9: Juli | C9: STIMULATE | H9: / | I9: / | O9: / | P9: / | V9: / | W9: / | AC9: / | AD9: / | AI9: =SUM(D9:G9,J9:N9,Q9:U9,X9:AB9,AE9:AH9) -> 0 | AJ9: 0 | AK9: 0
C10: ENKOS | H10: / | I10: / | O10: / | P10: / | V10: / | W10: / | AC10: / | AD10: / | AI10: =SUM(D10:G10,J10:N10,Q10:U10,X10:AB10,AE10:AH10) -> 0
B11: 23 Arbeitstage | C11: ESSENCE | H11: / | I11: / | O11: / | P11: / | V11: / | W11: / | AC11: / | AD11: / | AI11: =SUM(D11:G11,J11:N11,Q11:U11,X11:AB11,AE11:AH11) -> 0
C12: IDLE | H12: / | I12: / | O12: / | P12: / | V12: / | W12: / | AC12: / | AD12: / | AI12: =SUM(D12:G12,J12:N12,Q12:U12,X12:AB12,AE12:AH12) -> 0
B13: 184 | C13: AREALIGHT | H13: / | I13: / | O13: / | P13: / | V13: / | W13: / | AC13: / | AD13: / | AI13: =SUM(D13:G13,J13:N13,Q13:U13,X13:AB13,AE13:AH13) -> 0
C14: MR ASSIST | H14: / | I14: / | O14: / | P14: / | V14: / | W14: / | AC14: / | AD14: / | AI14: =SUM(D14:G14,J14:N14,Q14:U14,X14:AB14,AE14:AH14) -> 0
C15: HEATFLUXTEX | H15: / | I15: / | O15: / | P15: / | V15: / | W15: / | AC15: / | AD15: / | AI15: =SUM(D15:G15,J15:N15,Q15:U15,X15:AB15,AE15:AH15) -> 0
C16: TEXWELD | D16: 8 | E16: 8 | F16: 8 | G16: 8 | H16: / | I16: / | J16: 8 | K16: 8 | L16: 8 | M16: 8 | N16: 8 | O16: / | P16: / | Q16: U | R16: U | S16: U | T16: U | U16: U | V16: / | W16: / | X16: U | Y16: U | Z16: U | AA16: U | AB16: U | AC16: / | AD16: / | AE16: 8 | AF16: 8 | AG16: 8 | AH16: 8 | AI16: =SUM(D16:G16,J16:N16,Q16:U16,X16:AB16,AE16:AH16) -> 104
AI17: =SUM(AI9:AI16) -> 104 | AK17: =SUM(AI17,AJ9:AK9) -> 104
B18: August | C18: STIMULATE | E18: / | F18: / | L18: / | M18: / | S18: / | T18: / | Z18: / | AA18: / | AG18: / | AH18: / | AI18: =SUM(D18,G18:K18,N18:R18,U18:Y18,AB18:AF18) -> 0 | AJ18: 0 | AK18: 0
C19: ENKOS | E19: / | F19: / | L19: / | M19: / | S19: / | T19: / | Z19: / | AA19: / | AG19: / | AH19: / | AI19: =SUM(D19,G19:K19,N19:R19,U19:Y19,AB19:AF19) -> 0
B20: 21 Arbeitstage | C20: ESSENCE | E20: / | F20: / | L20: / | M20: / | S20: / | T20: / | Z20: / | AA20: / | AG20: / | AH20: / | AI20: =SUM(D20,G20:K20,N20:R20,U20:Y20,AB20:AF20) -> 0
C21: IDLE | E21: / | F21: / | L21: / | M21: / | S21: / | T21: / | Z21: / | AA21: / | AG21: / | AH21: / | AI21: =SUM(D21,G21:K21,N21:R21,U21:Y21,AB21:AF21) -> 0
B22: 168 | C22: AREALIGHT | E22: / | F22: / | L22: / | M22: / | S22: / | T22: / | Z22: / | AA22: / | AG22: / | AH22: / | AI22: =SUM(D22,G22:K22,N22:R22,U22:Y22,AB22:AF22) -> 0
C23: MR ASSIST | E23: / | F23: / | L23: / | M23: / | S23: / | T23: / | Z23: / | AA23: / | AG23: / | AH23: / | AI23: =SUM(D23,G23:K23,N23:R23,U23:Y23,AB23:AF23) -> 0
C24: HEATFLUXTEX | E24: / | F24: / | L24: / | M24: / | S24: / | T24: / | Z24: / | AA24: / | AG24: / | AH24: / | AI24: =SUM(D24,G24:K24,N24:R24,U24:Y24,AB24:AF24) -> 0
C25: TEXWELD | D25: 8 | E25: / | F25: / | G25: 8 | H25: 8 | I25: 8 | J25: 8 | K25: 8 | L25: / | M25: / | N25: 8 | O25: 8 | P25: 8 | Q25: 8 | R25: 8 | S25: / | T25: / | U25: 8 | V25: 8 | W25: 8 | X25: 8 | Y25: 8 | Z25: / | AA25: / | AB25: 8 | AC25: 8 | AD25: 8 | AE25: 8 | AF25: 8 | AG25: / | AH25: / | AI25: =SUM(D25,G25:K25,N25:R25,U25:Y25,AB25:AF25) -> 168
AI26: =SUM(AI18:AI25) -> 168 | AK26: =SUM(AI26,AJ18:AK18) -> 168
B27: September | C27: STIMULATE | I27: / | J27: / | P27: / | Q27: / | W27: / | X27: / | AD27: / | AE27: / | AF27: U | AG27: U | AI27: =SUM(D27:H27,K27:O27,R27:V27,Y27:AC27,AF27:AG27) -> 0 | AJ27: 16 | AK27: 0
C28: ENKOS | I28: / | J28: / | P28: / | Q28: / | W28: / | X28: / | AD28: / | AE28: / | AF28: U | AG28: U | AI28: =SUM(D28:H28,K28:O28,R28:V28,Y28:AC28,AF28:AG28) -> 0
B29: 22 Arbeitstage | C29: ESSENCE | I29: / | J29: / | P29: / | Q29: / | W29: / | X29: / | AD29: / | AE29: / | AF29: U | AG29: U | AI29: =SUM(D29:H29,K29:O29,R29:V29,Y29:AC29,AF29:AG29) -> 0
C30: IDLE | I30: / | J30: / | P30: / | Q30: / | W30: / | X30: / | AD30: / | AE30: / | AF30: U | AG30: U | AI30: =SUM(D30:H30,K30:O30,R30:V30,Y30:AC30,AF30:AG30) -> 0
B31: 176 | C31: AREALIGHT | I31: / | J31: / | P31: / | Q31: / | W31: / | X31: / | AD31: / | AE31: / | AF31: U | AG31: U | AI31: =SUM(D31:H31,K31:O31,R31:V31,Y31:AC31,AF31:AG31) -> 0
C32: MR ASSIST | I32: / | J32: / | P32: / | Q32: / | W32: / | X32: / | AD32: / | AE32: / | AF32: U | AG32: U | AI32: =SUM(D32:H32,K32:O32,R32:V32,Y32:AC32,AF32:AG32) -> 0
C33: HEATFLUXTEX | I33: / | J33: / | P33: / | Q33: / | W33: / | X33: / | AD33: / | AE33: / | AF33: U | AG33: U | AI33: =SUM(D33:H33,K33:O33,R33:V33,Y33:AC33,AF33:AG33) -> 0
C34: TEXWELD | D34: 8 | E34: 8 | F34: 8 | G34: 8 | H34: 8 | I34: / | J34: / | K34: 8 | L34: 8 | M34: 8 | N34: 8 | O34: 8 | P34: / | Q34: / | R34: 8 | S34: 8 | T34: 8 | U34: 8 | V34: 8 | W34: / | X34: / | Y34: 8 | Z34: 8 | AA34: 8 | AB34: 8 | AC34: 8 | AD34: / | AE34: / | AF34: U | AG34: U | AI34: =SUM(D34:H34,K34:O34,R34:V34,Y34:AC34,AF34:AG34) -> 160
AI35: =SUM(AI27:AI34) -> 160 | AK35: =SUM(AI35,AJ27:AK27) -> 176
B36: Oktober | C36: POLYVETEX | D36: U | E36: U | F36: F | G36: / | H36: / | N36: / | O36: / | U36: / | V36: / | AB36: / | AC36: / | AH36: F | AI36: =SUM(D36:E36,I36:M36,P36:T36,W36:AA36,AD36:AG36) -> 0 | AJ36: 16 | AK36: 16
C37: ENKOS | D37: U | E37: U | F37: F | G37: / | H37: / | N37: / | O37: / | U37: / | V37: / | AB37: / | AC37: / | AH37: F | AI37: =SUM(D37:E37,I37:M37,P37:T37,W37:AA37,AD37:AG37) -> 0
B38: 22 Arbeitstage | C38: ESSENCE | D38: U | E38: U | F38: F | G38: / | H38: / | N38: / | O38: / | U38: / | V38: / | AB38: / | AC38: / | AH38: F | AI38: =SUM(D38:E38,I38:M38,P38:T38,W38:AA38,AD38:AG38) -> 0
B39: 2 F | C39: IDLE | D39: U | E39: U | F39: F | G39: / | H39: / | N39: / | O39: / | U39: / | V39: / | AB39: / | AC39: / | AH39: F | AI39: =SUM(D39:E39,I39:M39,P39:T39,W39:AA39,AD39:AG39) -> 0
B40: 184 | C40: AREALIGHT | D40: U | E40: U | F40: F | G40: / | H40: / | N40: / | O40: / | U40: / | V40: / | AB40: / | AC40: / | AH40: F | AI40: =SUM(D40:E40,I40:M40,P40:T40,W40:AA40,AD40:AG40) -> 0
C41: FLEXTEXIR | D41: U | E41: U | F41: F | G41: / | H41: / | N41: / | O41: / | U41: / | V41: / | AB41: / | AC41: / | AH41: F | AI41: 0
...

Sheet Daniela Z
A1: Jahr | B1: 2025 | F1: / = Wochenende | AA1: 4 Stunden - 24 Dezember
A2: MA: | B2: Mitarbeiter: | C2: Daniela Zavec | F2: U=Urlaub | AA2: 4 Stunden - 31 Dezember
F3: K=Krank
F4: KK=Kindkrank
F5: F=Feiertag
D7: Arbeitstag
A8: Monat | B8: Monat | C8: Projekt | D8: 1 | E8: 2 | F8: 3 | G8: 4 | H8: 5 | I8: 6 | J8: 7 | K8: 8 | L8: 9 | M8: 10 | N8: 11 | O8: 12 | P8: 13 | Q8: 14 | R8: 15 | S8: 16 | T8: 17 | U8: 18 | V8: 19 | W8: 20 | X8: 21 | Y8: 22 | Z8: 23 | AA8: 24 | AB8: 25 | AC8: 26 | AD8: 27 | AE8: 28 | AF8: 29 | AG8: 30 | AH8: 31 | AI8: Arbeitsstunden | AJ8: Urlaubstunden | AK8: Feiertag
B9: Juli | C9: STIMULATE | H9: / | I9: / | O9: / | P9: / | V9: / | W9: / | AC9: / | AD9: / | AI9: =SUM(D9:G9,J9:N9,Q9:U9,X9:AB9,AE9:AH9) -> 0 | AJ9: 0 | AK9: 0
C10: ENKOS | H10: / | I10: / | O10: / | P10: / | V10: / | W10: / | AB10: 8 | AC10: / | AD10: / | AE10: 8 | AF10: 8 | AG10: 8 | AH10: 8 | AI10: =SUM(D10:G10,J10:N10,Q10:U10,X10:AB10,AE10:AH10) -> 40
B11: 23 Arbeitstage | C11: ESSENCE | H11: / | I11: / | O11: / | P11: / | V11: / | W11: / | AC11: / | AD11: / | AI11: =SUM(D11:G11,J11:N11,Q11:U11,X11:AB11,AE11:AH11) -> 0
C12: IDLE | H12: / | I12: / | J12: 8 | K12: 8 | L12: 8 | M12: 8 | N12: 8 | O12: / | P12: / | Q12: 8 | R12: 8 | S12: 8 | T12: 8 | U12: 8 | V12: / | W12: / | AC12: / | AD12: / | AI12: =SUM(D12:G12,J12:N12,Q12:U12,X12:AB12,AE12:AH12) -> 80
B13: 184 | C13: AREALIGHT | H13: / | I13: / | O13: / | P13: / | V13: / | W13: / | AC13: / | AD13: / | AI13: =SUM(D13:G13,J13:N13,Q13:U13,X13:AB13,AE13:AH13) -> 0
C14: MR ASSIST | D14: 8 | E14: 8 | F14: 8 | G14: 8 | H14: / | I14: / | O14: / | P14: / | V14: / | W14: / | X14: 8 | Y14: 8 | Z14: 8 | AA14: 8 | AC14: / | AD14: / | AI14: =SUM(D14:G14,J14:N14,Q14:U14,X14:AB14,AE14:AH14) -> 64
C15: HEATFLUXTEX | H15: / | I15: / | O15: / | P15: / | V15: / | W15: / | AC15: / | AD15: / | AI15: =SUM(D15:G15,J15:N15,Q15:U15,X15:AB15,AE15:AH15) -> 0
C16: TEXWELD | H16: / | I16: / | O16: / | P16: / | V16: / | W16: / | AC16: / | AD16: / | AI16: =SUM(D16:G16,J16:N16,Q16:U16,X16:AB16,AE16:AH16) -> 0
AI17: =SUM(AI9:AI16) -> 184 | AK17: =SUM(AI17,AJ9:AK9) -> 184
B18: August | C18: STIMULATE | E18: / | F18: / | L18: / | M18: / | S18: / | T18: / | Z18: / | AA18: / | AG18: / | AH18: / | AI18: =SUM(D18,G18:K18,N18:R18,U18:Y18,AB18:AF18) -> 0 | AJ18: 0 | AK18: 0
C19: ENKOS | E19: / | F19: / | L19: / | M19: / | N19: 8 | O19: 8 | P19: 8 | Q19: 8 | R19: 8 | S19: / | T19: / | Z19: / | AA19: / | AG19: / | AH19: / | AI19: =SUM(D19,G19:K19,N19:R19,U19:Y19,AB19:AF19) -> 40
B20: 21 Arbeitstage | C20: ESSENCE | E20: / | F20: / | L20: / | M20: / | S20: / | T20: / | Z20: / | AA20: / | AG20: / | AH20: / | AI20: =SUM(D20,G20:K20,N20:R20,U20:Y20,AB20:AF20) -> 0
C21: IDLE | E21: / | F21: / | L21: / | M21: / | S21: / | T21: / | U21: 8 | V21: 8 | W21: 8 | X21: 8 | Y21: 8 | Z21: / | AA21: / | AB21: 8 | AC21: 8 | AD21: 8 | AE21: 8 | AF21: 8 | AG21: / | AH21: / | AI21: =SUM(D21,G21:K21,N21:R21,U21:Y21,AB21:AF21) -> 80
B22: 168 | C22: AREALIGHT | E22: / | F22: / | L22: / | M22: / | S22: / | T22: / | Z22: / | AA22: / | AG22: / | AH22: / | AI22: =SUM(D22,G22:K22,N22:R22,U22:Y22,AB22:AF22) -> 0
C23: MR ASSIST | D23: 8 | E23: / | F23: / | G23: 8 | H23: 8 | J23: 8 | K23: 8 | L23: / | M23: / | S23: / | T23: / | Z23: / | AA23: / | AG23: / | AH23: / | AI23: =SUM(D23,G23:K23,N23:R23,U23:Y23,AB23:AF23) -> 40
C24: HEATFLUXTEX | E24: / | F24: / | L24: / | M24: / | S24: / | T24: / | Z24: / | AA24: / | AG24: / | AH24: / | AI24: =SUM(D24,G24:K24,N24:R24,U24:Y24,AB24:AF24) -> 0
C25: TEXWELD | E25: / | F25: / | L25: / | M25: / | S25: / | T25: / | Z25: / | AA25: / | AG25: / | AH25: / | AI25: =SUM(D25,G25:K25,N25:R25,U25:Y25,AB25:AF25) -> 0
AI26: =SUM(AI18:AI25) -> 160 | AK26: =SUM(AI26,AJ18:AK18) -> 160
B27: September | C27: STIMULATE | I27: / | J27: / | P27: / | Q27: / | W27: / | X27: / | AD27: / | AE27: / | AI27: =SUM(D27:H27,K27:O27,R27:V27,Y27:AC27,AF27:AG27) -> 0 | AJ27: 0 | AK27: 0
C28: ENKOS | I28: / | J28: / | P28: / | Q28: / | W28: / | X28: / | AD28: / | AE28: / | AI28: =SUM(D28:H28,K28:O28,R28:V28,Y28:AC28,AF28:AG28) -> 0
B29: 22 Arbeitstage | C29: ESSENCE | I29: / | J29: / | P29: / | Q29: / | W29: / | X29: / | AD29: / | AE29: / | AI29: =SUM(D29:H29,K29:O29,R29:V29,Y29:AC29,AF29:AG29) -> 0
C30: IDLE | D30: 8 | E30: 8 | F30: 8 | G30: 8 | H30: 8 | I30: / | J30: / | P30: / | Q30: / | W30: / | X30: / | AD30: / | AE30: / | AI30: =SUM(D30:H30,K30:O30,R30:V30,Y30:AC30,AF30:AG30) -> 40
B31: 176 | C31: AREALIGHT | I31: / | J31: / | P31: / | Q31: / | W31: / | X31: / | AD31: / | AE31: / | AI31: =SUM(D31:H31,K31:O31,R31:V31,Y31:AC31,AF31:AG31) -> 0
C32: MR ASSIST | I32: / | J32: / | P32: / | Q32: / | W32: / | X32: / | AD32: / | AE32: / | AI32: =SUM(D32:H32,K32:O32,R32:V32,Y32:AC32,AF32:AG32) -> 0
C33: HEATFLUXTEX | I33: / | J33: / | K33: 8 | L33: 8 | M33: 8 | N33: 8 | O33: 8 | P33: / | Q33: / | R33: 8 | S33: 8 | T33: 8 | U33: 8 | V33: 8 | W33: / | X33: / | Y33: 8 | Z33: 8 | AA33: 8 | AB33: 8 | AC33: 8 | AD33: / | AE33: / | AI33: =SUM(D33:H33,K33:O33,R33:V33,Y33:AC33,AF33:AG33) -> 120
C34: TEXWELD | I34: / | J34: / | P34: / | Q34: / | W34: / | X34: / | AD34: / | AE34: / | AI34: =SUM(D34:H34,K34:O34,R34:V34,Y34:AC34,AF34:AG34) -> 0
AI35: =SUM(AI27:AI34) -> 160 | AK35: =SUM(AI35,AJ27:AK27) -> 160
B36: Oktober | C36: POLYVETEX | F36: F | G36: / | H36: / | N36: / | O36: / | U36: / | V36: / | AB36: / | AC36: / | AH36: F | AI36: =SUM(D36:E36,I36:M36,P36:T36,W36:AA36,AD36:AG36) -> 0 | AK36: 16
C37: ENKOS | D37: 8 | E37: 8 | F37: F | G37: / | H37: / | N37: / | O37: / | U37: / | V37: / | AB37: / | AC37: / | AH37: F | AI37: =SUM(D37:E37,I37:M37,P37:T37,W37:AA37,AD37:AG37) -> 16
B38: 22 Arbeitstage | C38: ESSENCE | F38: F | G38: / | H38: / | N38: / | O38: / | U38: / | V38: / | AB38: / | AC38: / | AH38: F | AI38: =SUM(D38:E38,I38:M38,P38:T38,W38:AA38,AD38:AG38) -> 0
B39: 2 F | C39: IDLE | F39: F | G39: / | H39: / | I39: 8 | J39: 8 | K39: 8 | L39: 8 | M39: 8 | N39: / | O39: / | P39: 8 | Q39: 8 | R39: 8 | S39: 8 | T39: 8 | U39: / | V39: / | AB39: / | AC39: / | AH39: F | AI39: =SUM(D39:E39,I39:M39,P39:T39,W39:AA39,AD39:AG39) -> 80
B40: 184 | C40: AREALIGHT | F40: F | G40: / | H40: / | N40: / | O40: / | U40: / | V40: / | AB40: / | AC40: / | AH40: F | AI40: =SUM(D40:E40,I40:M40,P40:T40,W40:AA40,AD40:AG40) -> 0
C41: FLEXTEXIR | F41: F | G41: / | H41: / | N41: / | O41: / | U41: / | V41: / | AB41: / | AC41: / | AH41: F | AI41: 0
...

Sheet MA2 (3)
A1: Jahr | B1: 2025 | F1: / = Wochenende | AA1: 46015 | AB1: 4 Stunden
A2: MA: | B2: Mitarbeiter: | F2: U=Urlaub | AA2: 46022 | AB2: 4 Stunden
F3: K=Krank
F4: KK=Kindkrank
F5: F=Feiertag
D7: Arbeitstag
A8: Monat | B8: Monat | C8: Projekt | D8: 1 | E8: 2 | F8: 3 | G8: 4 | H8: 5 | I8: 6 | J8: 7 | K8: 8 | L8: 9 | M8: 10 | N8: 11 | O8: 12 | P8: 13 | Q8: 14 | R8: 15 | S8: 16 | T8: 17 | U8: 18 | V8: 19 | W8: 20 | X8: 21 | Y8: 22 | Z8: 23 | AA8: 24 | AB8: 25 | AC8: 26 | AD8: 27 | AE8: 28 | AF8: 29 | AG8: 30 | AH8: 31 | AI8: Arbeitsstunden | AJ8: Urlaubstunden | AK8: Feiertag
B9: August | C9: STIMULATE | E9: / | F9: / | L9: / | M9: / | S9: / | T9: / | Z9: / | AA9: / | AG9: / | AH9: / | AI9: =SUM(D9,G9:K9,N9:R9,U9:Y9,AB9:AF9) -> 0 | AJ9: 0 | AK9: 0
C10: ENKOS | E10: / | F10: / | L10: / | M10: / | S10: / | T10: / | Z10: / | AA10: / | AG10: / | AH10: / | AI10: =SUM(D10,G10:K10,N10:R10,U10:Y10,AB10:AF10) -> 0
B11: 21 Arbeitstage | C11: ESSENCE | E11: / | F11: / | L11: / | M11: / | S11: / | T11: / | Z11: / | AA11: / | AG11: / | AH11: / | AI11: =SUM(D11,G11:K11,N11:R11,U11:Y11,AB11:AF11) -> 0
C12: IDLE | E12: / | F12: / | L12: / | M12: / | S12: / | T12: / | Z12: / | AA12: / | AG12: / | AH12: / | AI12: =SUM(D12,G12:K12,N12:R12,U12:Y12,AB12:AF12) -> 0
B13: 168 | C13: AREALIGHT | E13: / | F13: / | L13: / | M13: / | S13: / | T13: / | Z13: / | AA13: / | AG13: / | AH13: / | AI13: =SUM(D13,G13:K13,N13:R13,U13:Y13,AB13:AF13) -> 0
C14: MR ASSIST | E14: / | F14: / | L14: / | M14: / | S14: / | T14: / | Z14: / | AA14: / | AG14: / | AH14: / | AI14: =SUM(D14,G14:K14,N14:R14,U14:Y14,AB14:AF14) -> 0
C15: HEATFLUXTEX | E15: / | F15: / | L15: / | M15: / | S15: / | T15: / | Z15: / | AA15: / | AG15: / | AH15: / | AI15: =SUM(D15,G15:K15,N15:R15,U15:Y15,AB15:AF15) -> 0
C16: TEXWELD | E16: / | F16: / | L16: / | M16: / | S16: / | T16: / | Z16: / | AA16: / | AG16: / | AH16: / | AI16: =SUM(D16,G16:K16,N16:R16,U16:Y16,AB16:AF16) -> 0
AI17: =SUM(AI9:AI16) -> 0 | AK17: =SUM(AI17,AJ9:AK9) -> 0
B18: September | C18: STIMULATE | I18: / | J18: / | P18: / | Q18: / | W18: / | X18: / | AD18: / | AE18: / | AI18: =SUM(D18:H18,K18:O18,R18:V18,Y18:AC18,AF18:AG18) -> 0 | AJ18: 0 | AK18: 0
C19: ENKOS | I19: / | J19: / | P19: / | Q19: / | W19: / | X19: / | AD19: / | AE19: / | AI19: =SUM(D19:H19,K19:O19,R19:V19,Y19:AC19,AF19:AG19) -> 0
B20: 22 Arbeitstage | C20: ESSENCE | I20: / | J20: / | P20: / | Q20: / | W20: / | X20: / | AD20: / | AE20: / | AI20: =SUM(D20:H20,K20:O20,R20:V20,Y20:AC20,AF20:AG20) -> 0
C21: IDLE | I21: / | J21: / | P21: / | Q21: / | W21: / | X21: / | AD21: / | AE21: / | AI21: =SUM(D21:H21,K21:O21,R21:V21,Y21:AC21,AF21:AG21) -> 0
B22: 176 | C22: AREALIGHT | I22: / | J22: / | P22: / | Q22: / | W22: / | X22: / | AD22: / | AE22: / | AI22: =SUM(D22:H22,K22:O22,R22:V22,Y22:AC22,AF22:AG22) -> 0
C23: MR ASSIST | I23: / | J23: / | P23: / | Q23: / | W23: / | X23: / | AD23: / | AE23: / | AI23: =SUM(D23:H23,K23:O23,R23:V23,Y23:AC23,AF23:AG23) -> 0
C24: HEATFLUXTEX | I24: / | J24: / | P24: / | Q24: / | W24: / | X24: / | AD24: / | AE24: / | AI24: =SUM(D24:H24,K24:O24,R24:V24,Y24:AC24,AF24:AG24) -> 0
C25: TEXWELD | I25: / | J25: / | P25: / | Q25: / | W25: / | X25: / | AD25: / | AE25: / | AI25: =SUM(D25:H25,K25:O25,R25:V25,Y25:AC25,AF25:AG25) -> 0
AI26: =SUM(AI18:AI25) -> 0 | AK26: =SUM(AI26,AJ18:AK18) -> 0
B27: Oktober | C27: POLYVETEX | F27: F | G27: / | H27: / | N27: / | O27: / | U27: / | V27: / | AB27: / | AC27: / | AH27: F | AI27: =SUM(D27:E27,I27:M27,P27:T27,W27:AA27,AD27:AG27) -> 0 | AK27: 0
C28: ENKOS | F28: F | G28: / | H28: / | N28: / | O28: / | U28: / | V28: / | AB28: / | AC28: / | AH28: F | AI28: =SUM(D28:E28,I28:M28,P28:T28,W28:AA28,AD28:AG28) -> 0
B29: 22 Arbeitstage | C29: ESSENCE | F29: F | G29: / | H29: / | N29: / | O29: / | U29: / | V29: / | AB29: / | AC29: / | AH29: F | AI29: =SUM(D29:E29,I29:M29,P29:T29,W29:AA29,AD29:AG29) -> 0
B30: 2 F | C30: IDLE | F30: F | G30: / | H30: / | N30: / | O30: / | U30: / | V30: / | AB30: / | AC30: / | AH30: F | AI30: =SUM(D30:E30,I30:M30,P30:T30,W30:AA30,AD30:AG30) -> 0
B31: 184 | C31: AREALIGHT | F31: F | G31: / | H31: / | N31: / | O31: / | U31: / | V31: / | AB31: / | AC31: / | AH31: F | AI31: =SUM(D31:E31,I31:M31,P31:T31,W31:AA31,AD31:AG31) -> 0
C32: FLEXTEXIR | F32: F | G32: / | H32: / | N32: / | O32: / | U32: / | V32: / | AB32: / | AC32: / | AH32: F | AI32: 0
C33: MR ASSIST | F33: F | G33: / | H33: / | N33: / | O33: / | U33: / | V33: / | AB33: / | AC33: / | AH33: F | AI33: =SUM(D33:E33,I33:M33,P33:T33,W33:AA33,AD33:AG33) -> 0
C34: HEATFLUXTEX | F34: F | G34: / | H34: / | N34: / | O34: / | U34: / | V34: / | AB34: / | AC34: / | AH34: F | AI34: =SUM(D34:E34,I34:M34,P34:T34,W34:AA34,AD34:AG34) -> 0
C35: TEXWELD | F35: F | G35: / | H35: / | N35: / | O35: / | U35: / | V35: / | AB35: / | AC35: / | AH35: F | AI35: =SUM(D35:E35,I35:M35,P35:T35,W35:AA35,AD35:AG35) -> 0
AI36: =SUM(AI27:AI35) -> 0 | AK36: =SUM(AI36,AJ27:AK27) -> 0
B37: November | C37: POLYVETEX | D37: / | E37: / | K37: / | L37: / | R37: / | S37: / | Y37: / | Z37: / | AF37: / | AG37: / | AI37: =SUM(F37:J37,M37:Q37,T37:X37,AA37:AE37) -> 0
C38: ENKOS | D38: / | E38: / | K38: / | L38: / | R38: / | S38: / | Y38: / | Z38: / | AF38: / | AG38: / | AI38: =SUM(F38:J38,M38:Q38,T38:X38,AA38:AE38) -> 0
B39: 20 Arbeitstage | C39: ESSENCE | D39: / | E39: / | K39: / | L39: / | R39: / | S39: / | Y39: / | Z39: / | AF39: / | AG39: / | AI39: =SUM(F39:J39,M39:Q39,T39:X39,AA39:AE39) -> 0
C40: IDLE | D40: / | E40: / | K40: / | L40: / | R40: / | S40: / | Y40: / | Z40: / | AF40: / | AG40: / | AI40: =SUM(F40:J40,M40:Q40,T40:X40,AA40:AE40) -> 0
B41: 160 | C41: AREALIGHT | D41: / | E41: / | K41: / | L41: / | R41: / | S41: / | Y41: / | Z41: / | AF41: / | AG41: / | AI41: =SUM(F41:J41,M41:Q41,T41:X41,AA41:AE41) -> 0
...

Sheet Stunden pro Projekt
A2: Stunden pro Projekt | B2: Monat
B3: Januar | C3: Februar | D3: März | E3: April | F3: Mai | G3: Juni | H3: Juli | I3: August | J3: September | K3: Oktober | L3: November | M3: Dezember | N3: Total
A5: POLYVETEX | B5: Januar | C5: Februar | D5: März | E5: April | F5: Mai | G5: Juni | H5: Juli | I5: August | J5: September | K5: Oktober | L5: November | M5: Dezember
A6: Lars | B6: ='Lars B'!AI9 -> 0 | C6: ='Lars B'!AI20 -> 0 | D6: ='Lars B'!AI31 -> 0 | E6: ='Lars B'!AI42 -> 0 | F6: ='Lars B'!AL20 -> 0 | G6: ='Lars B'!AL31 -> 0 | H6: ='Lars B'!AO9 -> 0 | I6: ='Lars B'!AO20 -> 0 | J6: ='Lars B'!AO31 -> 0 | K6: ='Lars B'!AR9 -> 0 | L6: ='Lars B'!AR20 -> 0 | M6: ='Lars B'!AR31 -> 0 | N6: =SUM(B6:D6) -> 0
A7: Lena | N7: =SUM(B7:D7) -> 0
A8: Sabrina | N8: =SUM(B8:D8) -> 0
A9: Karen | N9: =SUM(B9:D9) -> 0
A10: Ron | N10: =SUM(B10:D10) -> 0
A11: Lucas | N11: =SUM(B11:D11) -> 0
A12: Mayuresh | N12: =SUM(B12:D12) -> 0
A13: Daniela | N13: =SUM(B13:D13) -> 0
